# Author: thecraww
# From: Minecraft Forums
weight=1
embed_into_distance=1
acceptable_target_blocks=sand-1
dimensions=6,5,7
allowable_overhang=2
max_cut_in=2
cut_in_buffer=1
max_leveling=2
leveling_buffer=1
preserve_water=0
preserve_lava=0
preserve_plants=0

rule1=0,100,sand-1,fpsp:tile.redSandstone
rule2=0,100,sand-1,fpsp:tile.redSandstone
rule3=1,50,sand-1,fpsp:tile.redSandstone
rule4=1,50,fpsp:tile.redSandstone
rule5=2,33,fpsp:tile.redSandstone
rule6=1,33,fpsp:tile.redSandstone
rule7=0,1,HardMobSpawn

layer
2,2,2,2,2,2,2
2,1,1,1,1,1,2
2,1,1,1,1,1,2
2,1,1,1,1,1,2
2,2,2,2,2,2,2
endlayer

layer
3,3,3,3,3,3,3
3,0,7,0,7,0,3
3,7,0,7,0,7,3
3,0,7,0,7,0,3
3,3,3,3,3,3,3
endlayer

layer
3,3,3,3,3,3,3
3,0,0,0,0,0,3
3,0,0,0,0,0,3
3,0,0,0,0,0,3
3,3,3,3,3,3,3
endlayer

layer
3,3,3,3,3,3,3
3,0,0,0,0,0,3
3,0,0,0,0,0,3
3,0,0,0,0,0,3
3,3,3,3,3,3,3
endlayer

layer
4,5,0,0,0,5,4
5,0,0,0,0,0,5
0,0,0,0,0,0,0
5,0,0,0,0,0,5
4,5,0,0,0,5,4
endlayer

layer
6,0,0,0,0,0,6
0,0,0,0,0,0,5
0,0,0,0,0,0,0
0,0,0,0,0,0,5
6,0,0,0,0,0,6
endlayer